2025-07-18 18:05:54,956 [INFO] Coroutine 0 started with instance ID: 21932_1752847543_coro_0
2025-07-18 18:05:54,956 [INFO] Attempting to generate a new email alias via SimpleLogin...
2025-07-18 18:06:05,359 [INFO] âœ… Generated random proxy: 'http://ehztbehm:ry2444y66wok@198.23.239.134:6540'
2025-07-18 18:06:11,162 [ERROR] Fatal error during email generation: 
Traceback (most recent call last):
  File "C:\Users\Me\Workspace\Coding\webshare proxy generator\.venv\Lib\site-packages\httpx\_transports\default.py", line 101, in map_httpcore_exceptions
    yield
  File "C:\Users\Me\Workspace\Coding\webshare proxy generator\.venv\Lib\site-packages\httpx\_transports\default.py", line 394, in handle_async_request
    resp = await self._pool.handle_async_request(req)
           ^^^^^^^^^^^^^^^^^^^^^^^^^^^^^^^^^^^^^^^^^^
  File "C:\Users\Me\Workspace\Coding\webshare proxy generator\.venv\Lib\site-packages\httpcore\_async\connection_pool.py", line 256, in handle_async_request
    raise exc from None
  File "C:\Users\Me\Workspace\Coding\webshare proxy generator\.venv\Lib\site-packages\httpcore\_async\connection_pool.py", line 236, in handle_async_request
    response = await connection.handle_async_request(
               ^^^^^^^^^^^^^^^^^^^^^^^^^^^^^^^^^^^^^^
  File "C:\Users\Me\Workspace\Coding\webshare proxy generator\.venv\Lib\site-packages\httpcore\_async\http_proxy.py", line 288, in handle_async_request
    connect_response = await self._connection.handle_async_request(
                       ^^^^^^^^^^^^^^^^^^^^^^^^^^^^^^^^^^^^^^^^^^^^
  File "C:\Users\Me\Workspace\Coding\webshare proxy generator\.venv\Lib\site-packages\httpcore\_async\connection.py", line 101, in handle_async_request
    raise exc
  File "C:\Users\Me\Workspace\Coding\webshare proxy generator\.venv\Lib\site-packages\httpcore\_async\connection.py", line 78, in handle_async_request
    stream = await self._connect(request)
             ^^^^^^^^^^^^^^^^^^^^^^^^^^^^
  File "C:\Users\Me\Workspace\Coding\webshare proxy generator\.venv\Lib\site-packages\httpcore\_async\connection.py", line 124, in _connect
    stream = await self._network_backend.connect_tcp(**kwargs)
             ^^^^^^^^^^^^^^^^^^^^^^^^^^^^^^^^^^^^^^^^^^^^^^^^^
  File "C:\Users\Me\Workspace\Coding\webshare proxy generator\.venv\Lib\site-packages\httpcore\_backends\auto.py", line 31, in connect_tcp
    return await self._backend.connect_tcp(
           ^^^^^^^^^^^^^^^^^^^^^^^^^^^^^^^^
  File "C:\Users\Me\Workspace\Coding\webshare proxy generator\.venv\Lib\site-packages\httpcore\_backends\anyio.py", line 113, in connect_tcp
    with map_exceptions(exc_map):
         ^^^^^^^^^^^^^^^^^^^^^^^
  File "C:\Users\Me\AppData\Local\Programs\Python\Python312\Lib\contextlib.py", line 158, in __exit__
    self.gen.throw(value)
  File "C:\Users\Me\Workspace\Coding\webshare proxy generator\.venv\Lib\site-packages\httpcore\_exceptions.py", line 14, in map_exceptions
    raise to_exc(exc) from exc
httpcore.ConnectTimeout

The above exception was the direct cause of the following exception:

Traceback (most recent call last):
  File "C:\Users\Me\Workspace\Coding\webshare proxy generator\main.py", line 196, in _generate_email
    response = await client.get('https://app.simplelogin.io/auth/login', headers={'User-Agent': random.choice(USER_AGENTS)})
               ^^^^^^^^^^^^^^^^^^^^^^^^^^^^^^^^^^^^^^^^^^^^^^^^^^^^^^^^^^^^^^^^^^^^^^^^^^^^^^^^^^^^^^^^^^^^^^^^^^^^^^^^^^^^^
  File "C:\Users\Me\Workspace\Coding\webshare proxy generator\.venv\Lib\site-packages\httpx\_client.py", line 1768, in get
    return await self.request(
           ^^^^^^^^^^^^^^^^^^^
  File "C:\Users\Me\Workspace\Coding\webshare proxy generator\.venv\Lib\site-packages\httpx\_client.py", line 1540, in request
    return await self.send(request, auth=auth, follow_redirects=follow_redirects)
           ^^^^^^^^^^^^^^^^^^^^^^^^^^^^^^^^^^^^^^^^^^^^^^^^^^^^^^^^^^^^^^^^^^^^^^
  File "C:\Users\Me\Workspace\Coding\webshare proxy generator\.venv\Lib\site-packages\httpx\_client.py", line 1629, in send
    response = await self._send_handling_auth(
               ^^^^^^^^^^^^^^^^^^^^^^^^^^^^^^^
  File "C:\Users\Me\Workspace\Coding\webshare proxy generator\.venv\Lib\site-packages\httpx\_client.py", line 1657, in _send_handling_auth
    response = await self._send_handling_redirects(
               ^^^^^^^^^^^^^^^^^^^^^^^^^^^^^^^^^^^^
  File "C:\Users\Me\Workspace\Coding\webshare proxy generator\.venv\Lib\site-packages\httpx\_client.py", line 1694, in _send_handling_redirects
    response = await self._send_single_request(request)
               ^^^^^^^^^^^^^^^^^^^^^^^^^^^^^^^^^^^^^^^^
  File "C:\Users\Me\Workspace\Coding\webshare proxy generator\.venv\Lib\site-packages\httpx\_client.py", line 1730, in _send_single_request
    response = await transport.handle_async_request(request)
               ^^^^^^^^^^^^^^^^^^^^^^^^^^^^^^^^^^^^^^^^^^^^^
  File "C:\Users\Me\Workspace\Coding\webshare proxy generator\.venv\Lib\site-packages\httpx\_transports\default.py", line 393, in handle_async_request
    with map_httpcore_exceptions():
         ^^^^^^^^^^^^^^^^^^^^^^^^^
  File "C:\Users\Me\AppData\Local\Programs\Python\Python312\Lib\contextlib.py", line 158, in __exit__
    self.gen.throw(value)
  File "C:\Users\Me\Workspace\Coding\webshare proxy generator\.venv\Lib\site-packages\httpx\_transports\default.py", line 118, in map_httpcore_exceptions
    raise mapped_exc(message) from exc
httpx.ConnectTimeout
2025-07-18 18:06:11,235 [ERROR] Registration failed: 
Traceback (most recent call last):
  File "C:\Users\Me\Workspace\Coding\webshare proxy generator\.venv\Lib\site-packages\httpx\_transports\default.py", line 101, in map_httpcore_exceptions
    yield
  File "C:\Users\Me\Workspace\Coding\webshare proxy generator\.venv\Lib\site-packages\httpx\_transports\default.py", line 394, in handle_async_request
    resp = await self._pool.handle_async_request(req)
           ^^^^^^^^^^^^^^^^^^^^^^^^^^^^^^^^^^^^^^^^^^
  File "C:\Users\Me\Workspace\Coding\webshare proxy generator\.venv\Lib\site-packages\httpcore\_async\connection_pool.py", line 256, in handle_async_request
    raise exc from None
  File "C:\Users\Me\Workspace\Coding\webshare proxy generator\.venv\Lib\site-packages\httpcore\_async\connection_pool.py", line 236, in handle_async_request
    response = await connection.handle_async_request(
               ^^^^^^^^^^^^^^^^^^^^^^^^^^^^^^^^^^^^^^
  File "C:\Users\Me\Workspace\Coding\webshare proxy generator\.venv\Lib\site-packages\httpcore\_async\http_proxy.py", line 288, in handle_async_request
    connect_response = await self._connection.handle_async_request(
                       ^^^^^^^^^^^^^^^^^^^^^^^^^^^^^^^^^^^^^^^^^^^^
  File "C:\Users\Me\Workspace\Coding\webshare proxy generator\.venv\Lib\site-packages\httpcore\_async\connection.py", line 101, in handle_async_request
    raise exc
  File "C:\Users\Me\Workspace\Coding\webshare proxy generator\.venv\Lib\site-packages\httpcore\_async\connection.py", line 78, in handle_async_request
    stream = await self._connect(request)
             ^^^^^^^^^^^^^^^^^^^^^^^^^^^^
  File "C:\Users\Me\Workspace\Coding\webshare proxy generator\.venv\Lib\site-packages\httpcore\_async\connection.py", line 124, in _connect
    stream = await self._network_backend.connect_tcp(**kwargs)
             ^^^^^^^^^^^^^^^^^^^^^^^^^^^^^^^^^^^^^^^^^^^^^^^^^
  File "C:\Users\Me\Workspace\Coding\webshare proxy generator\.venv\Lib\site-packages\httpcore\_backends\auto.py", line 31, in connect_tcp
    return await self._backend.connect_tcp(
           ^^^^^^^^^^^^^^^^^^^^^^^^^^^^^^^^
  File "C:\Users\Me\Workspace\Coding\webshare proxy generator\.venv\Lib\site-packages\httpcore\_backends\anyio.py", line 113, in connect_tcp
    with map_exceptions(exc_map):
         ^^^^^^^^^^^^^^^^^^^^^^^
  File "C:\Users\Me\AppData\Local\Programs\Python\Python312\Lib\contextlib.py", line 158, in __exit__
    self.gen.throw(value)
  File "C:\Users\Me\Workspace\Coding\webshare proxy generator\.venv\Lib\site-packages\httpcore\_exceptions.py", line 14, in map_exceptions
    raise to_exc(exc) from exc
httpcore.ConnectTimeout

The above exception was the direct cause of the following exception:

Traceback (most recent call last):
  File "C:\Users\Me\Workspace\Coding\webshare proxy generator\main.py", line 376, in register
    alias_info = await self._generate_email()
                 ^^^^^^^^^^^^^^^^^^^^^^^^^^^^
  File "C:\Users\Me\Workspace\Coding\webshare proxy generator\main.py", line 196, in _generate_email
    response = await client.get('https://app.simplelogin.io/auth/login', headers={'User-Agent': random.choice(USER_AGENTS)})
               ^^^^^^^^^^^^^^^^^^^^^^^^^^^^^^^^^^^^^^^^^^^^^^^^^^^^^^^^^^^^^^^^^^^^^^^^^^^^^^^^^^^^^^^^^^^^^^^^^^^^^^^^^^^^^
  File "C:\Users\Me\Workspace\Coding\webshare proxy generator\.venv\Lib\site-packages\httpx\_client.py", line 1768, in get
    return await self.request(
           ^^^^^^^^^^^^^^^^^^^
  File "C:\Users\Me\Workspace\Coding\webshare proxy generator\.venv\Lib\site-packages\httpx\_client.py", line 1540, in request
    return await self.send(request, auth=auth, follow_redirects=follow_redirects)
           ^^^^^^^^^^^^^^^^^^^^^^^^^^^^^^^^^^^^^^^^^^^^^^^^^^^^^^^^^^^^^^^^^^^^^^
  File "C:\Users\Me\Workspace\Coding\webshare proxy generator\.venv\Lib\site-packages\httpx\_client.py", line 1629, in send
    response = await self._send_handling_auth(
               ^^^^^^^^^^^^^^^^^^^^^^^^^^^^^^^
  File "C:\Users\Me\Workspace\Coding\webshare proxy generator\.venv\Lib\site-packages\httpx\_client.py", line 1657, in _send_handling_auth
    response = await self._send_handling_redirects(
               ^^^^^^^^^^^^^^^^^^^^^^^^^^^^^^^^^^^^
  File "C:\Users\Me\Workspace\Coding\webshare proxy generator\.venv\Lib\site-packages\httpx\_client.py", line 1694, in _send_handling_redirects
    response = await self._send_single_request(request)
               ^^^^^^^^^^^^^^^^^^^^^^^^^^^^^^^^^^^^^^^^
  File "C:\Users\Me\Workspace\Coding\webshare proxy generator\.venv\Lib\site-packages\httpx\_client.py", line 1730, in _send_single_request
    response = await transport.handle_async_request(request)
               ^^^^^^^^^^^^^^^^^^^^^^^^^^^^^^^^^^^^^^^^^^^^^
  File "C:\Users\Me\Workspace\Coding\webshare proxy generator\.venv\Lib\site-packages\httpx\_transports\default.py", line 393, in handle_async_request
    with map_httpcore_exceptions():
         ^^^^^^^^^^^^^^^^^^^^^^^^^
  File "C:\Users\Me\AppData\Local\Programs\Python\Python312\Lib\contextlib.py", line 158, in __exit__
    self.gen.throw(value)
  File "C:\Users\Me\Workspace\Coding\webshare proxy generator\.venv\Lib\site-packages\httpx\_transports\default.py", line 118, in map_httpcore_exceptions
    raise mapped_exc(message) from exc
httpx.ConnectTimeout
2025-07-18 18:06:11,237 [INFO] Total process finished in 16.28 seconds.
2025-07-18 18:06:11,237 [INFO] Coroutine 0 completed.
2025-07-18 18:06:11,237 [INFO] ---DONE LOGGER---
